<?xml version="1.0"?>
<!--    Author: Phoenix Fan
        Date: 08/10/2019 
		Modification: Add dynamics(damping and friction) to each joint.
					  Modify the velocity of each joint to 12.
-->
<robot name="biped_12DOF">

    <material name="white">
        <color rgba="1 1 1 1"/>
    </material>

    <material name="black">
        <color rgba="0.2 0.2 0.2 1"/>
    </material>

    <material name="blue">
        <color rgba="0 0 1 1"/>
    </material>


    <link name="base" >
        <inertial>
            <origin rpy = "0 0 0" xyz = "0 0 0" />
            <mass value = "0.0001" />
            <inertia ixx = "0.0001" ixy = "0.0" ixz = "0.0" iyy = "0.0001" iyz = "0.0" izz = "0.0001" />
        </inertial>
    </link>

    <link name="torso">
        <visual>
            <geometry>
                <box size="0.2 0.8 0.2"/>
            </geometry>
            <origin rpy="0 0 0" xyz="0 0 0"/>
            <material name="white"/>
        </visual>
        <collision>
            <geometry>
                <box size="0.2 0.8 0.2"/>
            </geometry>
            <origin rpy="0 0 0" xyz="0 0 0"/>
            <contact_coefficients mu="0.08" />
        </collision>
        <inertial>
            <mass value="32"/>
            <origin rpy="0 0 0" xyz="0 0 0"/>
            <inertia ixx = "0.0001" ixy = "0.0" ixz = "0.0" iyy = "0.0001" iyz = "0.0" izz = "0.0001" />
        </inertial>
    </link>
    <joint name="torso_to_base" type="continuous">
        <parent link="base"/>
        <child link="torso"/>
        <axis xyz="1 0 0"/>
        <origin rpy="0 0 0" xyz="0 0 0"/>
    </joint>

    <link name="right_visual_hip">
        <visual>
            <geometry>
                <box size="0 0 0"/>
            </geometry>
            <origin rpy="0 0 0" xyz="0 0 0"/>
            <material name="white"/>
        </visual>
        <collision>
            <geometry>
                <box size="0 0 0"/>
            </geometry>
            <origin rpy="0 0 0" xyz="0 0 0"/>
            <contact_coefficients mu="0.08" />
        </collision>
        <inertial>
            <mass value="0.0001"/>
            <origin rpy="0 0 0" xyz="0 0 0"/>
            <inertia ixx = "0.0001" ixy = "0.0" ixz = "0.0" iyy = "0.0001" iyz = "0.0" izz = "0.0001" />
        </inertial>
    </link>
    <joint name="torso_to_right_visual_hip" type="revolute">
        <parent link="torso"/>
        <child link="right_visual_hip"/>
        <dynamics damping="0.1" friction="0"/>
        <axis xyz="1 0 0"/>
        <origin rpy="0 0 0" xyz="0 -0.3 -0.1"/>
        <limit effort="500.0" lower="-0.785398" upper="0.785398" velocity="12"/>
    </joint>

    <link name="right_upper_thigh">
        <visual>
            <geometry>
                <box size="0.2 0.2 0.1"/>
            </geometry>
            <origin rpy="0 0 0" xyz="0 0 -0.05"/>
            <material name="black"/>
        </visual>
        <collision>
            <geometry>
                <box size="0.2 0.2 0.1"/>
            </geometry>
            <origin rpy="0 0 0" xyz="0 0 -0.05"/>
        </collision>
        <inertial>
            <mass value="4"/>
            <origin rpy="0 0 0" xyz="0 0 -0.05"/>
            <inertia ixx = "0.0001" ixy = "0.0" ixz = "0.0" iyy = "0.0001" iyz = "0.0" izz = "0.0001" />
        </inertial>
    </link>
    <joint name="right_visual_hip_to_upper_thigh" type="revolute">
        <parent link="right_visual_hip"/>
        <child link="right_upper_thigh"/>
        <dynamics damping="0.1" friction="0"/>
        <axis xyz="0 1 0"/>
        <limit effort="500.0" lower="-0.785398" upper="0.785398" velocity="12"/>
        <origin rpy="0 0 0" xyz="0 0 0"/>
    </joint>

    <link name="right_lower_thigh">
        <visual>
            <geometry>
                <box size="0.2 0.2 0.2"/>
            </geometry>
            <origin rpy="0 0 0" xyz="0 0 -0.1"/>
            <material name="blue"/>
        </visual>
        <collision>
            <geometry>
                <box size="0.2 0.2 0.2"/>
            </geometry>
            <origin rpy="0 0 0" xyz="0 0 -0.1"/>
        </collision>
        <inertial>
            <mass value="8"/>
            <origin rpy="0 0 0" xyz="0 0 -0.1"/>
            <inertia ixx = "0.0001" ixy = "0.0" ixz = "0.0" iyy = "0.0001" iyz = "0.0" izz = "0.0001" />
        </inertial>
    </link>
    <joint name="right_upper_thigh_to_lower_thigh" type="revolute">
        <parent link="right_upper_thigh"/>
        <child link="right_lower_thigh"/>
        <dynamics damping="0.1" friction="0"/>
        <axis xyz="0 0 1"/>
        <limit effort="500.0" lower="-0.785398" upper="0.785398" velocity="12"/>
        <origin rpy="0 0 0" xyz="0 0 -0.1"/>
    </joint>

    <link name="right_shank">
        <visual>
            <geometry>
                <box size="0.2 0.2 0.3"/>
            </geometry>
            <origin rpy="0 0 0" xyz="0 0 -0.15"/>
            <material name="white"/>
        </visual>
        <collision>
            <geometry>
                <box size="0.2 0.2 0.3"/>
            </geometry>
            <origin rpy="0 0 0" xyz="0 0 -0.15"/>
            <contact_coefficients mu="0.08" />
        </collision>
        <inertial>
            <mass value="12"/>
            <origin rpy="0 0 0" xyz="0 0 -0.15"/>
            <inertia ixx = "0.0001" ixy = "0.0" ixz = "0.0" iyy = "0.0001" iyz = "0.0" izz = "0.0001" />
        </inertial>
    </link>
    <joint name="right_thigh_to_shank" type="revolute">
        <parent link="right_lower_thigh"/>
        <child link="right_shank"/>
        <dynamics damping="0.1" friction="0"/>
        <axis xyz="0 1 0"/>
        <limit effort="500.0" lower="0" upper="2.96706" velocity="12"/>
        <origin rpy="0 0 0" xyz="0 0 -0.2"/>
    </joint>

    <link name="right_ankle">
        <visual>
            <geometry>
                <box size="0 0 0"/>
            </geometry>
            <origin rpy="0 0 0" xyz="0 0 0"/>
            <material name="white"/>
        </visual>
        <collision>
            <geometry>
                <box size="0 0 0"/>
            </geometry>
            <origin rpy="0 0 0" xyz="0 0 0"/>
            <contact_coefficients mu="0.08" />
        </collision>
        <inertial>
            <mass value="0.0001"/>
            <origin rpy="0 0 0" xyz="0 0 0"/>
            <inertia ixx = "0.0001" ixy = "0.0" ixz = "0.0" iyy = "0.0001" iyz = "0.0" izz = "0.0001" />
        </inertial>
    </link>
    <joint name="right_shank_to_ankle" type="revolute">
        <parent link="right_shank"/>
        <child link="right_ankle"/>
        <dynamics damping="0.1" friction="0"/>
        <axis xyz="1 0 0"/>
        <limit effort="500.0" lower="-0.261799" upper="0.261799" velocity="12"/>
        <origin rpy="0 0 0" xyz="0 0 -0.3"/>
    </joint>

    <link name="right_foot" >
        <visual>
            <geometry>
                <box size="0.3 0.2 0.1"/>
            </geometry>
            <origin rpy="0 0 0" xyz="0.05 0 -0.05"/>
            <material name="blue"/>
        </visual>
        <collision>
            <geometry>
                <box size="0.3 0.2 0.1"/>
            </geometry>
            <origin rpy="0 0 0" xyz="0.05 0 -0.05"/>
            <contact_coefficients mu="0.08" />
        </collision>
        <inertial>
            <mass value="6"/>
            <origin rpy="0 0 0" xyz="0.05 0 -0.05"/>
            <inertia ixx = "0.0001" ixy = "0.0" ixz = "0.0" iyy = "0.0001" iyz = "0.0" izz = "0.0001" />
        </inertial>
    </link>
    <joint name="right_ankle_to_foot" type="revolute">
        <parent link="right_ankle"/>
        <child link="right_foot"/>
        <dynamics damping="0.1" friction="0"/>
        <axis xyz="0 1 0"/>
        <limit effort="500.0" lower="-0.785398" upper="0.785398" velocity="12"/>
        <origin rpy="0 0 0" xyz="0 0 0"/>
    </joint>

    <link name="left_visual_hip">
        <visual>
            <geometry>
                <box size="0 0 0"/>
            </geometry>
            <origin rpy="0 0 0" xyz="0 0 0"/>
            <material name="white"/>
        </visual>
        <collision>
            <geometry>
                <box size="0 0 0"/>
            </geometry>
            <origin rpy="0 0 0" xyz="0 0 0"/>
            <contact_coefficients mu="0.08" />
        </collision>
        <inertial>
            <mass value="0.0001"/>
            <origin rpy="0 0 0" xyz="0 0 0"/>
            <inertia ixx = "0.0001" ixy = "0.0" ixz = "0.0" iyy = "0.0001" iyz = "0.0" izz = "0.0001" />
        </inertial>
    </link>
    <joint name="torso_to_left_visual_hip" type="revolute">
        <parent link="torso"/>
        <child link="left_visual_hip"/>
        <dynamics damping="0.1" friction="0"/>
        <axis xyz="1 0 0"/>
        <origin rpy="0 0 0" xyz="0 0.3 -0.1"/>
        <limit effort="500.0" lower="-0.785398" upper="0.785398" velocity="12"/>
    </joint>

    <link name="left_upper_thigh">
        <visual>
            <geometry>
                <box size="0.2 0.2 0.1"/>
            </geometry>
            <origin rpy="0 0 0" xyz="0 0 -0.05"/>
            <material name="black"/>
        </visual>
        <collision>
            <geometry>
                <box size="0.2 0.2 0.1"/>
            </geometry>
            <origin rpy="0 0 0" xyz="0 0 -0.05"/>
        </collision>
        <inertial>
            <mass value="4"/>
            <origin rpy="0 0 0" xyz="0 0 -0.05"/>
            <inertia ixx = "0.0001" ixy = "0.0" ixz = "0.0" iyy = "0.0001" iyz = "0.0" izz = "0.0001" />
        </inertial>
    </link>
    <joint name="left_visual_hip_to_upper_thigh" type="revolute">
        <parent link="left_visual_hip"/>
        <child link="left_upper_thigh"/>
        <dynamics damping="0.1" friction="0"/>
        <axis xyz="0 1 0"/>
        <limit effort="500.0" lower="-1.39626" upper="1.39626" velocity="12"/>
        <origin rpy="0 0 0" xyz="0 0 0"/>
    </joint>

    <link name="left_lower_thigh">
        <visual>
            <geometry>
                <box size="0.2 0.2 0.2"/>
            </geometry>
            <origin rpy="0 0 0" xyz="0 0 -0.1"/>
            <material name="blue"/>
        </visual>
        <collision>
            <geometry>
                <box size="0.2 0.2 0.2"/>
            </geometry>
            <origin rpy="0 0 0" xyz="0 0 -0.1"/>
        </collision>
        <inertial>
            <mass value="8"/>
            <origin rpy="0 0 0" xyz="0 0 -0.1"/>
            <inertia ixx = "0.0001" ixy = "0.0" ixz = "0.0" iyy = "0.0001" iyz = "0.0" izz = "0.0001" />
        </inertial>
    </link>
    <joint name="left_upper_thigh_to_lower_thigh" type="revolute">
        <parent link="left_upper_thigh"/>
        <child link="left_lower_thigh"/>
        <dynamics damping="0.1" friction="0"/>
        <axis xyz="0 0 1"/>
        <limit effort="500.0" lower="-0.785398" upper="0.785398" velocity="12"/>
        <origin rpy="0 0 0" xyz="0 0 -0.1"/>
    </joint>

    <link name="left_shank">
        <visual>
            <geometry>
                <box size="0.2 0.2 0.3"/>
            </geometry>
            <origin rpy="0 0 0" xyz="0 0 -0.15"/>
            <material name="white"/>
        </visual>
        <collision>
            <geometry>
                <box size="0.2 0.2 0.3"/>
            </geometry>
            <origin rpy="0 0 0" xyz="0 0 -0.15"/>
            <contact_coefficients mu="0.08" />
        </collision>
        <inertial>
            <mass value="12"/>
            <origin rpy="0 0 0" xyz="0 0 -0.15"/>
            <inertia ixx = "0.0001" ixy = "0.0" ixz = "0.0" iyy = "0.0001" iyz = "0.0" izz = "0.0001" />
        </inertial>
    </link>
    <joint name="left_thigh_to_shank" type="revolute">
        <parent link="left_lower_thigh"/>
        <child link="left_shank"/>
        <dynamics damping="0.1" friction="0"/>
        <axis xyz="0 1 0"/>
        <limit effort="500.0" lower="0" upper="2.96706" velocity="12"/>
        <origin rpy="0 0 0" xyz="0 0 -0.2"/>
    </joint>

    <link name="left_ankle">
        <visual>
            <geometry>
                <box size="0 0 0"/>
            </geometry>
            <origin rpy="0 0 0" xyz="0 0 0"/>
            <material name="white"/>
        </visual>
        <collision>
            <geometry>
                <box size="0 0 0"/>
            </geometry>
            <origin rpy="0 0 0" xyz="0 0 0"/>
            <contact_coefficients mu="0.08" />
        </collision>
        <inertial>
            <mass value="0.0001"/>
            <origin rpy="0 0 0" xyz="0 0 0"/>
            <inertia ixx = "0.0001" ixy = "0.0" ixz = "0.0" iyy = "0.0001" iyz = "0.0" izz = "0.0001" />
        </inertial>
    </link>
    <joint name="left_shank_to_ankle" type="revolute">
        <parent link="left_shank"/>
        <child link="left_ankle"/>
        <dynamics damping="0.1" friction="0"/>
        <axis xyz="1 0 0"/>
        <limit effort="500.0" lower="-0.261799" upper="0.261799" velocity="12"/>
        <origin rpy="0 0 0" xyz="0 0 -0.3"/>
    </joint>

    <link name="left_foot" >
        <visual>
            <geometry>
                <box size="0.3 0.2 0.1"/>
            </geometry>
            <origin rpy="0 0 0" xyz="0.05 0 -0.05"/>
            <material name="blue"/>
        </visual>
        <collision>
            <geometry>
                <box size="0.3 0.2 0.1"/>
            </geometry>
            <origin rpy="0 0 0" xyz="0.05 0 -0.05"/>
            <contact_coefficients mu="0.08" />
        </collision>
        <inertial>
            <mass value="6"/>
            <origin rpy="0 0 0" xyz="0.05 0 -0.05"/>
            <inertia ixx = "0.0001" ixy = "0.0" ixz = "0.0" iyy = "0.0001" iyz = "0.0" izz = "0.0001" />
        </inertial>
    </link>
    <joint name="left_ankle_to_foot" type="revolute">
        <parent link="left_ankle"/>
        <child link="left_foot"/>
        <dynamics damping="0.1" friction="0"/>
        <axis xyz="0 1 0"/>
        <limit effort="500.0" lower="-0.785398" upper="0.785398" velocity="12"/>
        <origin rpy="0 0 0" xyz="0 0 0"/>
    </joint>

</robot>
