<?xml version="1.0"?>
<!--    Author: Phoenix Fan
        Date: 01/11/2019 
        Update: Modify the weight of each link according to an academic paper 
                (http://www.oandplibrary.org/al/pdf/1964_01_044.pdf)
-->
<robot name="biped_6DOF">

    <material name="white">
        <color rgba="1 1 1 1"/>
    </material>

    <material name="black">
        <color rgba="0.2 0.2 0.2 1"/>
    </material>

    <material name="blue">
        <color rgba="0 0 1 1"/>
    </material>

    <link name="torso">
        <visual>
            <geometry>
                <box size="0.2 0.8 0.2"/>
            </geometry>
            <origin rpy="0 0 0" xyz="0 0 0"/>
            <material name="white"/>
        </visual>
        <collision>
            <geometry>
                <box size="0.2 0.8 0.2"/>
            </geometry>
            <origin rpy="0 0 0" xyz="0 0 0"/>
        </collision>
        <inertial>
            <mass value="36.6755"/>
            <origin rpy="0 0 0" xyz="0 0 0"/>
            <inertia ixx = "2.07827" ixy = "0" ixz = "0" iyy = "0.244503" iyz = "0" izz = "2.07827" />
        </inertial>
    </link>

    <link name="right_thigh">
        <visual>
            <geometry>
                <box size="0.2 0.2 0.3"/>
            </geometry>
            <origin rpy="0 0 0" xyz="0 0 -0.15"/>
            <material name="black"/>
        </visual>
        <collision>
            <geometry>
                <box size="0.2 0.2 0.3"/>
            </geometry>
            <origin rpy="0 0 0" xyz="0 0 -0.15"/>
        </collision>
        <inertial>
            <mass value="6.526"/>
            <origin rpy="0 0 0" xyz="0 0 -0.15"/>
            <inertia ixx = "0.0706983" ixy = "0" ixz = "0" iyy = "0.0706983" iyz = "0" izz = "0.0435066" />
        </inertial>
    </link>
    <joint name="torso_to_right_thigh" type="revolute">
        <parent link="torso"/>
        <child link="right_thigh"/>
        <axis xyz="0 1 0"/>
        <dynamics damping="0.1" friction="0.0001"/>
        <limit effort="1000.0" lower="-1.39626" upper="1.39626" velocity="12"/>
        <origin rpy="0 0 0" xyz="0 -0.3 -0.1"/>
    </joint>

    <link name="right_shank">
        <visual>
            <geometry>
                <box size="0.2 0.2 0.3"/>
            </geometry>
            <origin rpy="0 0 0" xyz="0 0 -0.15"/>
            <material name="white"/>
        </visual>
        <collision>
            <geometry>
                <box size="0.2 0.2 0.3"/>
            </geometry>
            <origin rpy="0 0 0" xyz="0 0 -0.15"/>
        </collision>
        <inertial>
            <mass value="2.52375"/>
            <origin rpy="0 0 0" xyz="0 0 -0.15"/>
            <inertia ixx = "0.0273406" ixy = "0" ixz = "0" iyy = "0.0273406" iyz = "0" izz = "0.016825" />
        </inertial>
    </link>
    <joint name="right_thigh_to_shank" type="revolute">
        <parent link="right_thigh"/>
        <child link="right_shank"/>
        <axis xyz="0 1 0"/>
        <dynamics damping="0.1" friction="0.0001"/>
        <limit effort="1000.0" lower="0" upper="2.96706" velocity="12"/>
        <origin rpy="0 0 0" xyz="0 0 -0.3"/>
    </joint>

    <link name="right_foot" >
        <visual>
            <geometry>
                <box size="0.3 0.2 0.1"/>
            </geometry>
            <origin rpy="0 0 0" xyz="0.05 0 -0.05"/>
            <material name="blue"/>
        </visual>
        <collision>
            <geometry>
                <box size="0.3 0.2 0.1"/>
            </geometry>
            <origin rpy="0 0 0" xyz="0.05 0 -0.05"/>
        </collision>
        <inertial>
            <mass value="1.0776"/>
            <origin rpy="0 0 0" xyz="0.05 0 -0.05"/>
            <inertia ixx = "0.00449" ixy = "0" ixz = "0" iyy = "0.00898" iyz = "0" izz = "0.011674" />
        </inertial>
    </link>
    <joint name="right_shank_to_foot" type="revolute">
        <parent link="right_shank"/>
        <child link="right_foot"/>
        <axis xyz="0 1 0"/>
        <dynamics damping="0.1" friction="0.0001"/>
        <limit effort="1000.0" lower="-0.785398" upper="0.785398" velocity="12"/>
        <origin rpy="0 0 0" xyz="0 0 -0.3"/>
    </joint>

<link name="left_thigh">
        <visual>
            <geometry>
                <box size="0.2 0.2 0.3"/>
            </geometry>
            <origin rpy="0 0 0" xyz="0 0 -0.15"/>
            <material name="black"/>
        </visual>
        <collision>
            <geometry>
                <box size="0.2 0.2 0.3"/>
            </geometry>
            <origin rpy="0 0 0" xyz="0 0 -0.15"/>
        </collision>
        <inertial>
            <mass value="6.526"/>
            <origin rpy="0 0 0" xyz="0 0 -0.15"/>
            <inertia ixx = "0.0706983" ixy = "0" ixz = "0" iyy = "0.0706983" iyz = "0" izz = "0.0435066" />
        </inertial>
    </link>
    <joint name="torso_to_left_thigh" type="revolute">
        <parent link="torso"/>
        <child link="left_thigh"/>
        <axis xyz="0 1 0"/>
        <dynamics damping="0.1" friction="0.0001"/>
        <limit effort="1000.0" lower="-1.39626" upper="1.39626" velocity="12"/>
        <origin rpy="0 0 0" xyz="0 0.3 -0.1"/>
    </joint>

    <link name="left_shank">
        <visual>
            <geometry>
                <box size="0.2 0.2 0.3"/>
            </geometry>
            <origin rpy="0 0 0" xyz="0 0 -0.15"/>
            <material name="white"/>
        </visual>
        <collision>
            <geometry>
                <box size="0.2 0.2 0.3"/>
            </geometry>
            <origin rpy="0 0 0" xyz="0 0 -0.15"/>
        </collision>
        <inertial>
            <mass value="2.52375"/>
            <origin rpy="0 0 0" xyz="0 0 -0.15"/>
            <inertia ixx = "0.0273406" ixy = "0" ixz = "0" iyy = "0.0273406" iyz = "0" izz = "0.016825" />
        </inertial>
    </link>
    <joint name="left_thigh_to_shank" type="revolute">
        <parent link="left_thigh"/>
        <child link="left_shank"/>
        <axis xyz="0 1 0"/>
        <dynamics damping="0.1" friction="0.0001"/>
        <limit effort="1000.0" lower="0" upper="2.96706" velocity="12"/>
        <origin rpy="0 0 0" xyz="0 0 -0.3"/>
    </joint>

    <link name="left_foot" >
        <visual>
            <geometry>
                <box size="0.3 0.2 0.1"/>
            </geometry>
            <origin rpy="0 0 0" xyz="0.05 0 -0.05"/>
            <material name="blue"/>
        </visual>
        <collision>
            <geometry>
                <box size="0.3 0.2 0.1"/>
            </geometry>
            <origin rpy="0 0 0" xyz="0.05 0 -0.05"/>
        </collision>
        <inertial>
            <mass value="1.0776"/>
            <origin rpy="0 0 0" xyz="0.05 0 -0.05"/>
            <inertia ixx = "0.00449" ixy = "0" ixz = "0" iyy = "0.00898" iyz = "0" izz = "0.011674" />
        </inertial>
    </link>
    <joint name="left_shank_to_foot" type="revolute">
        <parent link="left_shank"/>
        <child link="left_foot"/>
        <axis xyz="0 1 0"/>
        <dynamics damping="0.1" friction="0.0001"/>
        <limit effort="1000.0" lower="-0.785398" upper="0.785398" velocity="12"/>
        <origin rpy="0 0 0" xyz="0 0 -0.3"/>
    </joint>

</robot>
